

В языке C++ блоки `try-catch` используются для обработки исключений. Исключения — это механизмы обработки ошибок, которые позволяют программе реагировать на возникновение неожиданных ситуаций (например, деление на ноль, переполнение памяти и т.д.) и предпринимать соответствующие действия.

## Структура и использование `try-catch` блоков:

1. **Блок `try`**: Код, который может вызвать исключение, помещается в блок `try`.
2. **Блок `catch`**: Код, который обрабатывает исключение, помещается в блок `catch`.

### Пример использования `try-catch`:

```cpp
#include <iostream>
#include <stdexcept> // Для стандартных исключений

int main() {
    try {
        // Код, который может вызвать исключение
        int a = 10;
        int b = 0;
        if (b == 0) {
            throw std::runtime_error("Division by zero error");
        }
        int c = a / b;
        std::cout << "Result: " << c << std::endl;
    } catch (const std::runtime_error& e) {
        // Обработка исключения
        std::cerr << "Caught an exception: " << e.what() << std::endl;
    } catch (...) {
        // Общий обработчик для всех других исключений
        std::cerr << "Caught an unknown exception" << std::endl;
    }

    return 0;
}
```

### Объяснение примера:

1. **Блок `try`**:
   ```cpp
   try {
       int a = 10;
       int b = 0;
       if (b == 0) {
           throw std::runtime_error("Division by zero error");
       }
       int c = a / b;
       std::cout << "Result: " << c << std::endl;
   }
   ```
   Здесь мы пытаемся выполнить деление на ноль, что вызывает исключение `std::runtime_error`.

2. **Блок `catch`**:
   ```cpp
   catch (const std::runtime_error& e) {
       std::cerr << "Caught an exception: " << e.what() << std::endl;
   }
   catch (...) {
       std::cerr << "Caught an unknown exception" << std::endl;
   }
   ```
   В первом блоке `catch` мы ловим исключение типа `std::runtime_error` и выводим сообщение об ошибке. Во втором блоке `catch` ловим любые другие исключения, которые могут возникнуть.

### Основные моменты:

- **Оператор `throw`**: Используется для генерации исключения.
  ```cpp
  throw std::runtime_error("Error message");
  ```
- **Тип исключения**: В блоке `catch` можно указать конкретный тип исключения, чтобы обрабатывать различные типы ошибок по-разному.
  ```cpp
  catch (const std::runtime_error& e) {
      // Specific error handling
  }
  ```
- **Общий блок `catch`**: Можно использовать блок `catch(...)` для обработки всех типов исключений, которые не были пойманы ранее.
  ```cpp
  catch (...) {
      // Handle any exception
  }
  ```

Блоки `try-catch` в C++ обеспечивают мощный механизм для обработки ошибок и исключений, позволяя разработчикам писать более надежный и устойчивый к ошибкам код.


Оператор `throw` в языке C++ используется для генерации исключений. Исключение — это специальное событие, которое прерывает нормальный поток выполнения программы и передает управление обработчику исключений. Этот механизм позволяет программе реагировать на ошибки или другие исключительные ситуации, которые могут возникнуть во время выполнения программы.

## Основные аспекты оператора `throw`:

1. **Генерация исключения**: Когда возникает исключительная ситуация, оператор `throw` используется для генерации исключения.
2. **Тип исключения**: Оператор `throw` может использоваться для генерации исключений различных типов (например, встроенные типы, объекты классов стандартной библиотеки, пользовательские классы).
3. **Передача управления**: После генерации исключения управление передается первому подходящему блоку `catch`, который находится в текущем или внешнем контексте.

### Пример использования оператора `throw`:

```cpp
#include <iostream>
#include <stdexcept> // Для стандартных исключений

void divide(int a, int b) {
    if (b == 0) {
        throw std::runtime_error("Division by zero error");
    }
    std::cout << "Result: " << a / b << std::endl;
}

int main() {
    try {
        divide(10, 0);
    } catch (const std::runtime_error& e) {
        std::cerr << "Caught an exception: " << e.what() << std::endl;
    }

    return 0;
}
```

### Объяснение примера:

1. **Функция `divide`**:
   ```cpp
   void divide(int a, int b) {
       if (b == 0) {
           throw std::runtime_error("Division by zero error");
       }
       std::cout << "Result: " << a / b << std::endl;
   }
   ```
   В этой функции мы проверяем, не равен ли делитель нулю. Если делитель равен нулю, генерируется исключение типа `std::runtime_error` с сообщением "Division by zero error".

2. **Блок `try-catch` в `main`**:
   ```cpp
   int main() {
       try {
           divide(10, 0);
       } catch (const std::runtime_error& e) {
           std::cerr << "Caught an exception: " << e.what() << std::endl;
       }
       return 0;
   }
   ```
   В этом блоке `try` вызывается функция `divide`, которая может вызвать исключение. Если исключение возникает, управление передается блоку `catch`, который ловит исключение типа `std::runtime_error` и выводит сообщение об ошибке.

### Основные моменты:

- **Генерация исключений различных типов**: Оператор `throw` может использоваться для генерации исключений любых типов.
  ```cpp
  throw 20; // Генерация исключения типа int
  throw "An error occurred"; // Генерация исключения типа const char*
  throw std::runtime_error("Runtime error"); // Генерация исключения типа std::runtime_error
  ```

- **Пользовательские исключения**: Можно создавать собственные классы исключений и генерировать исключения этих типов.
  ```cpp
  class MyException : public std::exception {
  public:
      const char* what() const noexcept override {
          return "My custom exception";
      }
  };

  throw MyException();
  ```

- **Обработка исключений**: Исключения обрабатываются в блоках `catch`, которые могут обрабатывать различные типы исключений по-разному.
  ```cpp
  try {
      // Код, который может вызвать исключение
  } catch (const std::runtime_error& e) {
      // Обработка исключения типа std::runtime_error
  } catch (const MyException& e) {
      // Обработка исключения типа MyException
  } catch (...) {
      // Обработка всех других типов исключений
  }
  ```

Оператор `throw` в C++ является ключевым элементом механизма обработки исключений, обеспечивая надежный способ реагирования на ошибки и другие исключительные ситуации в программе.